{
 "cells": [
  {
   "cell_type": "markdown",
   "metadata": {},
   "source": [
    "# Establishing database connection, running the main query"
   ]
  },
  {
   "cell_type": "code",
   "execution_count": 1,
   "metadata": {},
   "outputs": [
    {
     "name": "stderr",
     "output_type": "stream",
     "text": [
      "\n",
      "A module that was compiled using NumPy 1.x cannot be run in\n",
      "NumPy 2.1.1 as it may crash. To support both 1.x and 2.x\n",
      "versions of NumPy, modules must be compiled with NumPy 2.0.\n",
      "Some module may need to rebuild instead e.g. with 'pybind11>=2.12'.\n",
      "\n",
      "If you are a user of the module, the easiest solution will be to\n",
      "downgrade to 'numpy<2' or try to upgrade the affected module.\n",
      "We expect that some modules will need time to support NumPy 2.\n",
      "\n",
      "Traceback (most recent call last):  File \"<frozen runpy>\", line 198, in _run_module_as_main\n",
      "  File \"<frozen runpy>\", line 88, in _run_code\n",
      "  File \"/Users/grandpierrenimrod/anaconda3/lib/python3.11/site-packages/ipykernel_launcher.py\", line 18, in <module>\n",
      "    app.launch_new_instance()\n",
      "  File \"/Users/grandpierrenimrod/anaconda3/lib/python3.11/site-packages/traitlets/config/application.py\", line 1075, in launch_instance\n",
      "    app.start()\n",
      "  File \"/Users/grandpierrenimrod/anaconda3/lib/python3.11/site-packages/ipykernel/kernelapp.py\", line 739, in start\n",
      "    self.io_loop.start()\n",
      "  File \"/Users/grandpierrenimrod/anaconda3/lib/python3.11/site-packages/tornado/platform/asyncio.py\", line 205, in start\n",
      "    self.asyncio_loop.run_forever()\n",
      "  File \"/Users/grandpierrenimrod/anaconda3/lib/python3.11/asyncio/base_events.py\", line 608, in run_forever\n",
      "    self._run_once()\n",
      "  File \"/Users/grandpierrenimrod/anaconda3/lib/python3.11/asyncio/base_events.py\", line 1936, in _run_once\n",
      "    handle._run()\n",
      "  File \"/Users/grandpierrenimrod/anaconda3/lib/python3.11/asyncio/events.py\", line 84, in _run\n",
      "    self._context.run(self._callback, *self._args)\n",
      "  File \"/Users/grandpierrenimrod/anaconda3/lib/python3.11/site-packages/ipykernel/kernelbase.py\", line 545, in dispatch_queue\n",
      "    await self.process_one()\n",
      "  File \"/Users/grandpierrenimrod/anaconda3/lib/python3.11/site-packages/ipykernel/kernelbase.py\", line 534, in process_one\n",
      "    await dispatch(*args)\n",
      "  File \"/Users/grandpierrenimrod/anaconda3/lib/python3.11/site-packages/ipykernel/kernelbase.py\", line 437, in dispatch_shell\n",
      "    await result\n",
      "  File \"/Users/grandpierrenimrod/anaconda3/lib/python3.11/site-packages/ipykernel/ipkernel.py\", line 362, in execute_request\n",
      "    await super().execute_request(stream, ident, parent)\n",
      "  File \"/Users/grandpierrenimrod/anaconda3/lib/python3.11/site-packages/ipykernel/kernelbase.py\", line 778, in execute_request\n",
      "    reply_content = await reply_content\n",
      "  File \"/Users/grandpierrenimrod/anaconda3/lib/python3.11/site-packages/ipykernel/ipkernel.py\", line 449, in do_execute\n",
      "    res = shell.run_cell(\n",
      "  File \"/Users/grandpierrenimrod/anaconda3/lib/python3.11/site-packages/ipykernel/zmqshell.py\", line 549, in run_cell\n",
      "    return super().run_cell(*args, **kwargs)\n",
      "  File \"/Users/grandpierrenimrod/anaconda3/lib/python3.11/site-packages/IPython/core/interactiveshell.py\", line 3075, in run_cell\n",
      "    result = self._run_cell(\n",
      "  File \"/Users/grandpierrenimrod/anaconda3/lib/python3.11/site-packages/IPython/core/interactiveshell.py\", line 3130, in _run_cell\n",
      "    result = runner(coro)\n",
      "  File \"/Users/grandpierrenimrod/anaconda3/lib/python3.11/site-packages/IPython/core/async_helpers.py\", line 128, in _pseudo_sync_runner\n",
      "    coro.send(None)\n",
      "  File \"/Users/grandpierrenimrod/anaconda3/lib/python3.11/site-packages/IPython/core/interactiveshell.py\", line 3334, in run_cell_async\n",
      "    has_raised = await self.run_ast_nodes(code_ast.body, cell_name,\n",
      "  File \"/Users/grandpierrenimrod/anaconda3/lib/python3.11/site-packages/IPython/core/interactiveshell.py\", line 3517, in run_ast_nodes\n",
      "    if await self.run_code(code, result, async_=asy):\n",
      "  File \"/Users/grandpierrenimrod/anaconda3/lib/python3.11/site-packages/IPython/core/interactiveshell.py\", line 3577, in run_code\n",
      "    exec(code_obj, self.user_global_ns, self.user_ns)\n",
      "  File \"/var/folders/95/p0pcx9mx4f9d6vz9fsgtn38r0000gn/T/ipykernel_47931/3684115445.py\", line 2, in <module>\n",
      "    import pandas as pd\n",
      "  File \"/Users/grandpierrenimrod/anaconda3/lib/python3.11/site-packages/pandas/__init__.py\", line 26, in <module>\n",
      "    from pandas.compat import (\n",
      "  File \"/Users/grandpierrenimrod/anaconda3/lib/python3.11/site-packages/pandas/compat/__init__.py\", line 27, in <module>\n",
      "    from pandas.compat.pyarrow import (\n",
      "  File \"/Users/grandpierrenimrod/anaconda3/lib/python3.11/site-packages/pandas/compat/pyarrow.py\", line 8, in <module>\n",
      "    import pyarrow as pa\n",
      "  File \"/Users/grandpierrenimrod/anaconda3/lib/python3.11/site-packages/pyarrow/__init__.py\", line 65, in <module>\n",
      "    import pyarrow.lib as _lib\n"
     ]
    },
    {
     "ename": "AttributeError",
     "evalue": "_ARRAY_API not found",
     "output_type": "error",
     "traceback": [
      "\u001b[0;31m---------------------------------------------------------------------------\u001b[0m",
      "\u001b[0;31mAttributeError\u001b[0m                            Traceback (most recent call last)",
      "\u001b[0;31mAttributeError\u001b[0m: _ARRAY_API not found"
     ]
    },
    {
     "name": "stderr",
     "output_type": "stream",
     "text": [
      "\n",
      "A module that was compiled using NumPy 1.x cannot be run in\n",
      "NumPy 2.1.1 as it may crash. To support both 1.x and 2.x\n",
      "versions of NumPy, modules must be compiled with NumPy 2.0.\n",
      "Some module may need to rebuild instead e.g. with 'pybind11>=2.12'.\n",
      "\n",
      "If you are a user of the module, the easiest solution will be to\n",
      "downgrade to 'numpy<2' or try to upgrade the affected module.\n",
      "We expect that some modules will need time to support NumPy 2.\n",
      "\n",
      "Traceback (most recent call last):  File \"<frozen runpy>\", line 198, in _run_module_as_main\n",
      "  File \"<frozen runpy>\", line 88, in _run_code\n",
      "  File \"/Users/grandpierrenimrod/anaconda3/lib/python3.11/site-packages/ipykernel_launcher.py\", line 18, in <module>\n",
      "    app.launch_new_instance()\n",
      "  File \"/Users/grandpierrenimrod/anaconda3/lib/python3.11/site-packages/traitlets/config/application.py\", line 1075, in launch_instance\n",
      "    app.start()\n",
      "  File \"/Users/grandpierrenimrod/anaconda3/lib/python3.11/site-packages/ipykernel/kernelapp.py\", line 739, in start\n",
      "    self.io_loop.start()\n",
      "  File \"/Users/grandpierrenimrod/anaconda3/lib/python3.11/site-packages/tornado/platform/asyncio.py\", line 205, in start\n",
      "    self.asyncio_loop.run_forever()\n",
      "  File \"/Users/grandpierrenimrod/anaconda3/lib/python3.11/asyncio/base_events.py\", line 608, in run_forever\n",
      "    self._run_once()\n",
      "  File \"/Users/grandpierrenimrod/anaconda3/lib/python3.11/asyncio/base_events.py\", line 1936, in _run_once\n",
      "    handle._run()\n",
      "  File \"/Users/grandpierrenimrod/anaconda3/lib/python3.11/asyncio/events.py\", line 84, in _run\n",
      "    self._context.run(self._callback, *self._args)\n",
      "  File \"/Users/grandpierrenimrod/anaconda3/lib/python3.11/site-packages/ipykernel/kernelbase.py\", line 545, in dispatch_queue\n",
      "    await self.process_one()\n",
      "  File \"/Users/grandpierrenimrod/anaconda3/lib/python3.11/site-packages/ipykernel/kernelbase.py\", line 534, in process_one\n",
      "    await dispatch(*args)\n",
      "  File \"/Users/grandpierrenimrod/anaconda3/lib/python3.11/site-packages/ipykernel/kernelbase.py\", line 437, in dispatch_shell\n",
      "    await result\n",
      "  File \"/Users/grandpierrenimrod/anaconda3/lib/python3.11/site-packages/ipykernel/ipkernel.py\", line 362, in execute_request\n",
      "    await super().execute_request(stream, ident, parent)\n",
      "  File \"/Users/grandpierrenimrod/anaconda3/lib/python3.11/site-packages/ipykernel/kernelbase.py\", line 778, in execute_request\n",
      "    reply_content = await reply_content\n",
      "  File \"/Users/grandpierrenimrod/anaconda3/lib/python3.11/site-packages/ipykernel/ipkernel.py\", line 449, in do_execute\n",
      "    res = shell.run_cell(\n",
      "  File \"/Users/grandpierrenimrod/anaconda3/lib/python3.11/site-packages/ipykernel/zmqshell.py\", line 549, in run_cell\n",
      "    return super().run_cell(*args, **kwargs)\n",
      "  File \"/Users/grandpierrenimrod/anaconda3/lib/python3.11/site-packages/IPython/core/interactiveshell.py\", line 3075, in run_cell\n",
      "    result = self._run_cell(\n",
      "  File \"/Users/grandpierrenimrod/anaconda3/lib/python3.11/site-packages/IPython/core/interactiveshell.py\", line 3130, in _run_cell\n",
      "    result = runner(coro)\n",
      "  File \"/Users/grandpierrenimrod/anaconda3/lib/python3.11/site-packages/IPython/core/async_helpers.py\", line 128, in _pseudo_sync_runner\n",
      "    coro.send(None)\n",
      "  File \"/Users/grandpierrenimrod/anaconda3/lib/python3.11/site-packages/IPython/core/interactiveshell.py\", line 3334, in run_cell_async\n",
      "    has_raised = await self.run_ast_nodes(code_ast.body, cell_name,\n",
      "  File \"/Users/grandpierrenimrod/anaconda3/lib/python3.11/site-packages/IPython/core/interactiveshell.py\", line 3517, in run_ast_nodes\n",
      "    if await self.run_code(code, result, async_=asy):\n",
      "  File \"/Users/grandpierrenimrod/anaconda3/lib/python3.11/site-packages/IPython/core/interactiveshell.py\", line 3577, in run_code\n",
      "    exec(code_obj, self.user_global_ns, self.user_ns)\n",
      "  File \"/var/folders/95/p0pcx9mx4f9d6vz9fsgtn38r0000gn/T/ipykernel_47931/3684115445.py\", line 2, in <module>\n",
      "    import pandas as pd\n",
      "  File \"/Users/grandpierrenimrod/anaconda3/lib/python3.11/site-packages/pandas/__init__.py\", line 49, in <module>\n",
      "    from pandas.core.api import (\n",
      "  File \"/Users/grandpierrenimrod/anaconda3/lib/python3.11/site-packages/pandas/core/api.py\", line 9, in <module>\n",
      "    from pandas.core.dtypes.dtypes import (\n",
      "  File \"/Users/grandpierrenimrod/anaconda3/lib/python3.11/site-packages/pandas/core/dtypes/dtypes.py\", line 24, in <module>\n",
      "    from pandas._libs import (\n",
      "  File \"/Users/grandpierrenimrod/anaconda3/lib/python3.11/site-packages/pyarrow/__init__.py\", line 65, in <module>\n",
      "    import pyarrow.lib as _lib\n"
     ]
    },
    {
     "ename": "AttributeError",
     "evalue": "_ARRAY_API not found",
     "output_type": "error",
     "traceback": [
      "\u001b[0;31m---------------------------------------------------------------------------\u001b[0m",
      "\u001b[0;31mAttributeError\u001b[0m                            Traceback (most recent call last)",
      "\u001b[0;31mAttributeError\u001b[0m: _ARRAY_API not found"
     ]
    },
    {
     "name": "stderr",
     "output_type": "stream",
     "text": [
      "\n",
      "A module that was compiled using NumPy 1.x cannot be run in\n",
      "NumPy 2.1.1 as it may crash. To support both 1.x and 2.x\n",
      "versions of NumPy, modules must be compiled with NumPy 2.0.\n",
      "Some module may need to rebuild instead e.g. with 'pybind11>=2.12'.\n",
      "\n",
      "If you are a user of the module, the easiest solution will be to\n",
      "downgrade to 'numpy<2' or try to upgrade the affected module.\n",
      "We expect that some modules will need time to support NumPy 2.\n",
      "\n",
      "Traceback (most recent call last):  File \"<frozen runpy>\", line 198, in _run_module_as_main\n",
      "  File \"<frozen runpy>\", line 88, in _run_code\n",
      "  File \"/Users/grandpierrenimrod/anaconda3/lib/python3.11/site-packages/ipykernel_launcher.py\", line 18, in <module>\n",
      "    app.launch_new_instance()\n",
      "  File \"/Users/grandpierrenimrod/anaconda3/lib/python3.11/site-packages/traitlets/config/application.py\", line 1075, in launch_instance\n",
      "    app.start()\n",
      "  File \"/Users/grandpierrenimrod/anaconda3/lib/python3.11/site-packages/ipykernel/kernelapp.py\", line 739, in start\n",
      "    self.io_loop.start()\n",
      "  File \"/Users/grandpierrenimrod/anaconda3/lib/python3.11/site-packages/tornado/platform/asyncio.py\", line 205, in start\n",
      "    self.asyncio_loop.run_forever()\n",
      "  File \"/Users/grandpierrenimrod/anaconda3/lib/python3.11/asyncio/base_events.py\", line 608, in run_forever\n",
      "    self._run_once()\n",
      "  File \"/Users/grandpierrenimrod/anaconda3/lib/python3.11/asyncio/base_events.py\", line 1936, in _run_once\n",
      "    handle._run()\n",
      "  File \"/Users/grandpierrenimrod/anaconda3/lib/python3.11/asyncio/events.py\", line 84, in _run\n",
      "    self._context.run(self._callback, *self._args)\n",
      "  File \"/Users/grandpierrenimrod/anaconda3/lib/python3.11/site-packages/ipykernel/kernelbase.py\", line 545, in dispatch_queue\n",
      "    await self.process_one()\n",
      "  File \"/Users/grandpierrenimrod/anaconda3/lib/python3.11/site-packages/ipykernel/kernelbase.py\", line 534, in process_one\n",
      "    await dispatch(*args)\n",
      "  File \"/Users/grandpierrenimrod/anaconda3/lib/python3.11/site-packages/ipykernel/kernelbase.py\", line 437, in dispatch_shell\n",
      "    await result\n",
      "  File \"/Users/grandpierrenimrod/anaconda3/lib/python3.11/site-packages/ipykernel/ipkernel.py\", line 362, in execute_request\n",
      "    await super().execute_request(stream, ident, parent)\n",
      "  File \"/Users/grandpierrenimrod/anaconda3/lib/python3.11/site-packages/ipykernel/kernelbase.py\", line 778, in execute_request\n",
      "    reply_content = await reply_content\n",
      "  File \"/Users/grandpierrenimrod/anaconda3/lib/python3.11/site-packages/ipykernel/ipkernel.py\", line 449, in do_execute\n",
      "    res = shell.run_cell(\n",
      "  File \"/Users/grandpierrenimrod/anaconda3/lib/python3.11/site-packages/ipykernel/zmqshell.py\", line 549, in run_cell\n",
      "    return super().run_cell(*args, **kwargs)\n",
      "  File \"/Users/grandpierrenimrod/anaconda3/lib/python3.11/site-packages/IPython/core/interactiveshell.py\", line 3075, in run_cell\n",
      "    result = self._run_cell(\n",
      "  File \"/Users/grandpierrenimrod/anaconda3/lib/python3.11/site-packages/IPython/core/interactiveshell.py\", line 3130, in _run_cell\n",
      "    result = runner(coro)\n",
      "  File \"/Users/grandpierrenimrod/anaconda3/lib/python3.11/site-packages/IPython/core/async_helpers.py\", line 128, in _pseudo_sync_runner\n",
      "    coro.send(None)\n",
      "  File \"/Users/grandpierrenimrod/anaconda3/lib/python3.11/site-packages/IPython/core/interactiveshell.py\", line 3334, in run_cell_async\n",
      "    has_raised = await self.run_ast_nodes(code_ast.body, cell_name,\n",
      "  File \"/Users/grandpierrenimrod/anaconda3/lib/python3.11/site-packages/IPython/core/interactiveshell.py\", line 3517, in run_ast_nodes\n",
      "    if await self.run_code(code, result, async_=asy):\n",
      "  File \"/Users/grandpierrenimrod/anaconda3/lib/python3.11/site-packages/IPython/core/interactiveshell.py\", line 3577, in run_code\n",
      "    exec(code_obj, self.user_global_ns, self.user_ns)\n",
      "  File \"/var/folders/95/p0pcx9mx4f9d6vz9fsgtn38r0000gn/T/ipykernel_47931/3684115445.py\", line 2, in <module>\n",
      "    import pandas as pd\n",
      "  File \"/Users/grandpierrenimrod/anaconda3/lib/python3.11/site-packages/pandas/__init__.py\", line 49, in <module>\n",
      "    from pandas.core.api import (\n",
      "  File \"/Users/grandpierrenimrod/anaconda3/lib/python3.11/site-packages/pandas/core/api.py\", line 28, in <module>\n",
      "    from pandas.core.arrays import Categorical\n",
      "  File \"/Users/grandpierrenimrod/anaconda3/lib/python3.11/site-packages/pandas/core/arrays/__init__.py\", line 1, in <module>\n",
      "    from pandas.core.arrays.arrow import ArrowExtensionArray\n",
      "  File \"/Users/grandpierrenimrod/anaconda3/lib/python3.11/site-packages/pandas/core/arrays/arrow/__init__.py\", line 5, in <module>\n",
      "    from pandas.core.arrays.arrow.array import ArrowExtensionArray\n",
      "  File \"/Users/grandpierrenimrod/anaconda3/lib/python3.11/site-packages/pandas/core/arrays/arrow/array.py\", line 50, in <module>\n",
      "    from pandas.core import (\n",
      "  File \"/Users/grandpierrenimrod/anaconda3/lib/python3.11/site-packages/pandas/core/ops/__init__.py\", line 8, in <module>\n",
      "    from pandas.core.ops.array_ops import (\n",
      "  File \"/Users/grandpierrenimrod/anaconda3/lib/python3.11/site-packages/pandas/core/ops/array_ops.py\", line 56, in <module>\n",
      "    from pandas.core.computation import expressions\n",
      "  File \"/Users/grandpierrenimrod/anaconda3/lib/python3.11/site-packages/pandas/core/computation/expressions.py\", line 21, in <module>\n",
      "    from pandas.core.computation.check import NUMEXPR_INSTALLED\n",
      "  File \"/Users/grandpierrenimrod/anaconda3/lib/python3.11/site-packages/pandas/core/computation/check.py\", line 5, in <module>\n",
      "    ne = import_optional_dependency(\"numexpr\", errors=\"warn\")\n",
      "  File \"/Users/grandpierrenimrod/anaconda3/lib/python3.11/site-packages/pandas/compat/_optional.py\", line 135, in import_optional_dependency\n",
      "    module = importlib.import_module(name)\n",
      "  File \"/Users/grandpierrenimrod/anaconda3/lib/python3.11/importlib/__init__.py\", line 126, in import_module\n",
      "    return _bootstrap._gcd_import(name[level:], package, level)\n",
      "  File \"/Users/grandpierrenimrod/anaconda3/lib/python3.11/site-packages/numexpr/__init__.py\", line 24, in <module>\n",
      "    from numexpr.interpreter import MAX_THREADS, use_vml, __BLOCK_SIZE1__\n"
     ]
    },
    {
     "ename": "AttributeError",
     "evalue": "_ARRAY_API not found",
     "output_type": "error",
     "traceback": [
      "\u001b[0;31m---------------------------------------------------------------------------\u001b[0m",
      "\u001b[0;31mAttributeError\u001b[0m                            Traceback (most recent call last)",
      "\u001b[0;31mAttributeError\u001b[0m: _ARRAY_API not found"
     ]
    },
    {
     "name": "stderr",
     "output_type": "stream",
     "text": [
      "\n",
      "A module that was compiled using NumPy 1.x cannot be run in\n",
      "NumPy 2.1.1 as it may crash. To support both 1.x and 2.x\n",
      "versions of NumPy, modules must be compiled with NumPy 2.0.\n",
      "Some module may need to rebuild instead e.g. with 'pybind11>=2.12'.\n",
      "\n",
      "If you are a user of the module, the easiest solution will be to\n",
      "downgrade to 'numpy<2' or try to upgrade the affected module.\n",
      "We expect that some modules will need time to support NumPy 2.\n",
      "\n",
      "Traceback (most recent call last):  File \"<frozen runpy>\", line 198, in _run_module_as_main\n",
      "  File \"<frozen runpy>\", line 88, in _run_code\n",
      "  File \"/Users/grandpierrenimrod/anaconda3/lib/python3.11/site-packages/ipykernel_launcher.py\", line 18, in <module>\n",
      "    app.launch_new_instance()\n",
      "  File \"/Users/grandpierrenimrod/anaconda3/lib/python3.11/site-packages/traitlets/config/application.py\", line 1075, in launch_instance\n",
      "    app.start()\n",
      "  File \"/Users/grandpierrenimrod/anaconda3/lib/python3.11/site-packages/ipykernel/kernelapp.py\", line 739, in start\n",
      "    self.io_loop.start()\n",
      "  File \"/Users/grandpierrenimrod/anaconda3/lib/python3.11/site-packages/tornado/platform/asyncio.py\", line 205, in start\n",
      "    self.asyncio_loop.run_forever()\n",
      "  File \"/Users/grandpierrenimrod/anaconda3/lib/python3.11/asyncio/base_events.py\", line 608, in run_forever\n",
      "    self._run_once()\n",
      "  File \"/Users/grandpierrenimrod/anaconda3/lib/python3.11/asyncio/base_events.py\", line 1936, in _run_once\n",
      "    handle._run()\n",
      "  File \"/Users/grandpierrenimrod/anaconda3/lib/python3.11/asyncio/events.py\", line 84, in _run\n",
      "    self._context.run(self._callback, *self._args)\n",
      "  File \"/Users/grandpierrenimrod/anaconda3/lib/python3.11/site-packages/ipykernel/kernelbase.py\", line 545, in dispatch_queue\n",
      "    await self.process_one()\n",
      "  File \"/Users/grandpierrenimrod/anaconda3/lib/python3.11/site-packages/ipykernel/kernelbase.py\", line 534, in process_one\n",
      "    await dispatch(*args)\n",
      "  File \"/Users/grandpierrenimrod/anaconda3/lib/python3.11/site-packages/ipykernel/kernelbase.py\", line 437, in dispatch_shell\n",
      "    await result\n",
      "  File \"/Users/grandpierrenimrod/anaconda3/lib/python3.11/site-packages/ipykernel/ipkernel.py\", line 362, in execute_request\n",
      "    await super().execute_request(stream, ident, parent)\n",
      "  File \"/Users/grandpierrenimrod/anaconda3/lib/python3.11/site-packages/ipykernel/kernelbase.py\", line 778, in execute_request\n",
      "    reply_content = await reply_content\n",
      "  File \"/Users/grandpierrenimrod/anaconda3/lib/python3.11/site-packages/ipykernel/ipkernel.py\", line 449, in do_execute\n",
      "    res = shell.run_cell(\n",
      "  File \"/Users/grandpierrenimrod/anaconda3/lib/python3.11/site-packages/ipykernel/zmqshell.py\", line 549, in run_cell\n",
      "    return super().run_cell(*args, **kwargs)\n",
      "  File \"/Users/grandpierrenimrod/anaconda3/lib/python3.11/site-packages/IPython/core/interactiveshell.py\", line 3075, in run_cell\n",
      "    result = self._run_cell(\n",
      "  File \"/Users/grandpierrenimrod/anaconda3/lib/python3.11/site-packages/IPython/core/interactiveshell.py\", line 3130, in _run_cell\n",
      "    result = runner(coro)\n",
      "  File \"/Users/grandpierrenimrod/anaconda3/lib/python3.11/site-packages/IPython/core/async_helpers.py\", line 128, in _pseudo_sync_runner\n",
      "    coro.send(None)\n",
      "  File \"/Users/grandpierrenimrod/anaconda3/lib/python3.11/site-packages/IPython/core/interactiveshell.py\", line 3334, in run_cell_async\n",
      "    has_raised = await self.run_ast_nodes(code_ast.body, cell_name,\n",
      "  File \"/Users/grandpierrenimrod/anaconda3/lib/python3.11/site-packages/IPython/core/interactiveshell.py\", line 3517, in run_ast_nodes\n",
      "    if await self.run_code(code, result, async_=asy):\n",
      "  File \"/Users/grandpierrenimrod/anaconda3/lib/python3.11/site-packages/IPython/core/interactiveshell.py\", line 3577, in run_code\n",
      "    exec(code_obj, self.user_global_ns, self.user_ns)\n",
      "  File \"/var/folders/95/p0pcx9mx4f9d6vz9fsgtn38r0000gn/T/ipykernel_47931/3684115445.py\", line 2, in <module>\n",
      "    import pandas as pd\n",
      "  File \"/Users/grandpierrenimrod/anaconda3/lib/python3.11/site-packages/pandas/__init__.py\", line 49, in <module>\n",
      "    from pandas.core.api import (\n",
      "  File \"/Users/grandpierrenimrod/anaconda3/lib/python3.11/site-packages/pandas/core/api.py\", line 28, in <module>\n",
      "    from pandas.core.arrays import Categorical\n",
      "  File \"/Users/grandpierrenimrod/anaconda3/lib/python3.11/site-packages/pandas/core/arrays/__init__.py\", line 1, in <module>\n",
      "    from pandas.core.arrays.arrow import ArrowExtensionArray\n",
      "  File \"/Users/grandpierrenimrod/anaconda3/lib/python3.11/site-packages/pandas/core/arrays/arrow/__init__.py\", line 5, in <module>\n",
      "    from pandas.core.arrays.arrow.array import ArrowExtensionArray\n",
      "  File \"/Users/grandpierrenimrod/anaconda3/lib/python3.11/site-packages/pandas/core/arrays/arrow/array.py\", line 64, in <module>\n",
      "    from pandas.core.arrays.masked import BaseMaskedArray\n",
      "  File \"/Users/grandpierrenimrod/anaconda3/lib/python3.11/site-packages/pandas/core/arrays/masked.py\", line 60, in <module>\n",
      "    from pandas.core import (\n",
      "  File \"/Users/grandpierrenimrod/anaconda3/lib/python3.11/site-packages/pandas/core/nanops.py\", line 52, in <module>\n",
      "    bn = import_optional_dependency(\"bottleneck\", errors=\"warn\")\n",
      "  File \"/Users/grandpierrenimrod/anaconda3/lib/python3.11/site-packages/pandas/compat/_optional.py\", line 135, in import_optional_dependency\n",
      "    module = importlib.import_module(name)\n",
      "  File \"/Users/grandpierrenimrod/anaconda3/lib/python3.11/importlib/__init__.py\", line 126, in import_module\n",
      "    return _bootstrap._gcd_import(name[level:], package, level)\n",
      "  File \"/Users/grandpierrenimrod/anaconda3/lib/python3.11/site-packages/bottleneck/__init__.py\", line 7, in <module>\n",
      "    from .move import (move_argmax, move_argmin, move_max, move_mean, move_median,\n"
     ]
    },
    {
     "ename": "AttributeError",
     "evalue": "_ARRAY_API not found",
     "output_type": "error",
     "traceback": [
      "\u001b[0;31m---------------------------------------------------------------------------\u001b[0m",
      "\u001b[0;31mAttributeError\u001b[0m                            Traceback (most recent call last)",
      "\u001b[0;31mAttributeError\u001b[0m: _ARRAY_API not found"
     ]
    }
   ],
   "source": [
    "import sqlite3\n",
    "import pandas as pd\n",
    "\n",
    "conn = sqlite3.connect('../data/FPA_FOD_20170508.sqlite')\n",
    "\n",
    "query_1 = \"\"\"\n",
    "        SELECT\n",
    "            FIRE_CODE, FIRE_NAME, FIRE_YEAR, datetime(DISCOVERY_DATE) AS DISCOVERY_DATE,\n",
    "            DISCOVERY_DOY, DISCOVERY_TIME, STAT_CAUSE_DESCR, datetime(CONT_DATE) AS CONT_DATE,\n",
    "            CONT_DOY, CONT_TIME, FIRE_SIZE, FIRE_SIZE_CLASS, LATITUDE, LONGITUDE, STATE, COUNTY\n",
    "        FROM\n",
    "            Fires\n",
    "        WHERE\n",
    "            COUNTY IS NOT NULL;\n",
    "        \"\"\"\n",
    "\n",
    "df_1 = pd.read_sql_query(query_1, conn)"
   ]
  },
  {
   "cell_type": "markdown",
   "metadata": {},
   "source": [
    "# Generating JSON file from the resulting dataframe"
   ]
  },
  {
   "cell_type": "code",
   "execution_count": 2,
   "metadata": {},
   "outputs": [],
   "source": [
    "df_1.to_json(\"./../../frontend/public/fires.json\", orient = \"records\", indent = 4)"
   ]
  },
  {
   "cell_type": "markdown",
   "metadata": {},
   "source": [
    "# Closing the connection to the database"
   ]
  },
  {
   "cell_type": "code",
   "execution_count": 3,
   "metadata": {},
   "outputs": [],
   "source": [
    "conn.close()"
   ]
  }
 ],
 "metadata": {
  "kernelspec": {
   "display_name": "base",
   "language": "python",
   "name": "python3"
  },
  "language_info": {
   "codemirror_mode": {
    "name": "ipython",
    "version": 3
   },
   "file_extension": ".py",
   "mimetype": "text/x-python",
   "name": "python",
   "nbconvert_exporter": "python",
   "pygments_lexer": "ipython3",
   "version": "3.11.8"
  }
 },
 "nbformat": 4,
 "nbformat_minor": 2
}
